<mujoco model="tiangong2pro_urdf">
  <option gravity='0 0 -9.81' solver='PGS'/>
  <option integrator="implicitfast" />
  <size njmax="500" nconmax="100" />
  <compiler angle="radian" meshdir="../meshes/" eulerseq="zyx"/>
  <default>
    <joint type="hinge" limited="true" />
  </default>
  <asset>
    <texture type="skybox" builtin="gradient" rgb1="0.3 0.5 0.7" rgb2="0 0 0" width="512" height="512" />
    <texture name="texplane" type="2d" builtin="checker" rgb1=".2 .3 .4" rgb2=".1 0.15 0.2" width="512" height="512" mark="cross" markrgb=".8 .8 .8" />
    <material name="matplane" reflectance="0.3" texture="texplane" texrepeat="1 1" texuniform="true" />
    <mesh name="pelvis" file="pelvis.STL"/>
    <mesh name="hip_roll_l_link" file="hip_roll_l_link.STL"/>
    <mesh name="hip_pitch_l_link" file="hip_pitch_l_link.STL"/>
    <mesh name="hip_yaw_l_link" file="hip_yaw_l_link.STL"/>
    <mesh name="knee_pitch_l_link" file="knee_pitch_l_link.STL"/>
    <mesh name="ankle_pitch_l_link" file="ankle_pitch_l_link.STL"/>
    <mesh name="ankle_roll_l_link" file="ankle_roll_l_link.STL"/>
    <mesh name="hip_roll_r_link" file="hip_roll_r_link.STL"/>
    <mesh name="hip_pitch_r_link" file="hip_pitch_r_link.STL"/>
    <mesh name="hip_yaw_r_link" file="hip_yaw_r_link.STL"/>
    <mesh name="knee_pitch_r_link" file="knee_pitch_r_link.STL"/>
    <mesh name="ankle_pitch_r_link" file="ankle_pitch_r_link.STL"/>
    <mesh name="ankle_roll_r_link" file="ankle_roll_r_link.STL"/>
    <mesh name="body_yaw_link" content_type="model/stl" file="body_yaw_link.STL"/>
    <mesh name="head_yaw_link" content_type="model/stl" file="head_yaw_link.STL"/>
    <mesh name="head_pitch_link" content_type="model/stl" file="head_pitch_link.STL"/>
    <mesh name="head_roll_link" content_type="model/stl" file="head_roll_link.STL"/>
    <mesh name="camera_head_link" content_type="model/stl" file="camera_head_link.STL"/>
    <mesh name="shoulder_pitch_l_link" content_type="model/stl" file="shoulder_pitch_l_link.STL"/>
    <mesh name="shoulder_roll_l_link" content_type="model/stl" file="shoulder_roll_l_link.STL"/>
    <mesh name="shoulder_yaw_l_link" content_type="model/stl" file="shoulder_yaw_l_link.STL"/>
    <mesh name="elbow_pitch_l_link" content_type="model/stl" file="elbow_pitch_l_link.STL"/>
    <mesh name="elbow_yaw_l_link" content_type="model/stl" file="elbow_yaw_l_link.STL"/>
    <mesh name="wrist_pitch_l_link" content_type="model/stl" file="wrist_pitch_l_link.STL"/>
    <mesh name="wrist_roll_l_link" content_type="model/stl" file="wrist_roll_l_link.STL"/>
    <mesh name="left_tcp_link" content_type="model/stl" file="left_tcp_link.STL"/>
    <mesh name="shoulder_pitch_r_link" content_type="model/stl" file="shoulder_pitch_r_link.STL"/>
    <mesh name="shoulder_roll_r_link" content_type="model/stl" file="shoulder_roll_r_link.STL"/>
    <mesh name="shoulder_yaw_r_link" content_type="model/stl" file="shoulder_yaw_r_link.STL"/>
    <mesh name="elbow_pitch_r_link" content_type="model/stl" file="elbow_pitch_r_link.STL"/>
    <mesh name="elbow_yaw_r_link" content_type="model/stl" file="elbow_yaw_r_link.STL"/>
    <mesh name="wrist_pitch_r_link" content_type="model/stl" file="wrist_pitch_r_link.STL"/>
    <mesh name="wrist_roll_r_link" content_type="model/stl" file="wrist_roll_r_link.STL"/>
    <mesh name="right_tcp_link" content_type="model/stl" file="right_tcp_link.STL"/>
    <mesh name="camera_body_front_link" content_type="model/stl" file="camera_body_front_link.STL"/>
    <mesh name="camera_body_back_link" content_type="model/stl" file="camera_body_back_link.STL"/>
    <mesh name="imu_link" content_type="model/stl" file="imu_link.STL"/>
  </asset>

  <worldbody>
    <light directional="true" diffuse=".4 .4 .4" specular="0.1 0.1 0.1" pos="0 0 5.0" dir="0 0 -1" castshadow="false" />
    <light directional="true" diffuse=".6 .6 .6" specular="0.2 0.2 0.2" pos="0 0 4" dir="0 0 -1" />
    <geom name="floor" pos="0 0 0" size="100 100 1" type="plane" material="matplane" margin="0.001" contype="1" conaffinity="15" friction="1 0.005 0.0001" />

    <body name="Base_link" pos="0 0 1.0">
      <freejoint name="root" />
      <inertial pos="0.001537 0.000283 0.177608" quat="0.997803 1.42418e-06 0.0154267 -0.0644277" mass="27.7717" diaginertia="0.952918 0.922015 0.196947"/>

      <geom type="mesh" rgba="0.752941 0.752941 0.752941 1" mesh="pelvis"/>
      <geom pos="0.0499 -0.0358 -0.03194" quat="1 0 0 0" type="mesh" rgba="0.752941 0.752941 0.752941 1" mesh="imu_link"/>
      <body name="hip_roll_l_link" pos="0 0.028 -0.0857">
        <inertial pos="-0.001848 0.055849 -0.036017" quat="0.242041 0.661501 0.270146 0.656394" mass="0.672983" diaginertia="0.0035288 0.00296741 0.00101678"/>
        <joint name="hip_roll_l_joint" pos="0 0 0" axis="1 0 0" range="-0.785398 0.785398" actuatorfrcrange="-235 235"/>
        <geom type="mesh" rgba="0.752941 0.752941 0.752941 1" mesh="hip_roll_l_link"/>
        <body name="hip_pitch_l_link" pos="0 0.122 -0.046">
          <inertial pos="0.001081 -8.8e-05 -0.013133" quat="0.703908 -0.0464278 -0.0604083 0.706193" mass="3.95191" diaginertia="0.0155995 0.0108766 0.00930186"/>
          <joint name="hip_pitch_l_joint" pos="0 0 0" axis="0 1 0" range="-2.79253 2.0944" actuatorfrcrange="-330 330"/>
          <geom type="mesh" rgba="0.752941 0.752941 0.752941 1" mesh="hip_pitch_l_link"/>
          <body name="hip_yaw_l_link" pos="0 -0.00015 -0.0987">
            <inertial pos="0.004102 -0.006542 -0.121068" quat="0.685682 -0.0129439 0.0149542 0.727633" mass="6.6708" diaginertia="0.0533758 0.0495596 0.0178685"/>
            <joint name="hip_yaw_l_joint" pos="0 0 0" axis="0 0 1" range="-1.0472 1.0472" actuatorfrcrange="-235 235"/>
            <geom type="mesh" rgba="0.752941 0.752941 0.752941 1" mesh="hip_yaw_l_link"/>
            <body name="knee_pitch_l_link" pos="0 0.00010715 -0.3013">
              <inertial pos="0.00018 0.001915 -0.178653" quat="0.741662 0.0200239 0.0403837 0.669257" mass="2.31269" diaginertia="0.0309319 0.0304477 0.00269639"/>
              <joint name="knee_pitch_l_joint" pos="0 0 0" axis="0 1 0" range="0 2.3911" actuatorfrcrange="-330 330"/>
              <geom type="mesh" rgba="0.752941 0.752941 0.752941 1" mesh="knee_pitch_l_link"/>
              <body name="ankle_pitch_l_link" pos="0 0 -0.4">
                <inertial pos="0 0 0" quat="0.5 0.5 -0.5 0.5" mass="0.111609" diaginertia="3.2e-05 1.8e-05 1.8e-05"/>
                <joint name="ankle_pitch_l_joint" pos="0 0 0" axis="0 1 0" range="-1.22173 0.523599" actuatorfrcrange="-55 55"/>
                <geom type="mesh" rgba="0.752941 0.752941 0.752941 1" mesh="ankle_pitch_l_link"/>
                <body name="ankle_roll_l_link">
                  <inertial pos="0.021235 0 -0.032883" quat="0 0.747289 0 0.6645" mass="1.01738" diaginertia="0.0063132 0.006055 0.000954799"/>
                  <joint name="ankle_roll_l_joint" pos="0 0 0" axis="1 0 0" range="-0.523599 0.523599" actuatorfrcrange="-55 55"/>
                  <geom type="mesh" rgba="0.752941 0.752941 0.752941 1" mesh="ankle_roll_l_link"/>
                </body>
              </body>
            </body>
          </body>
        </body>
      </body>
      <body name="hip_roll_r_link" pos="0 -0.028 -0.0857">
        <inertial pos="-0.001848 -0.055849 -0.036017" quat="-0.242041 0.661501 -0.270146 0.656394" mass="0.672983" diaginertia="0.0035288 0.00296741 0.00101678"/>
        <joint name="hip_roll_r_joint" pos="0 0 0" axis="1 0 0" range="-0.785398 0.785398" actuatorfrcrange="-235 235"/>
        <geom type="mesh" rgba="0.752941 0.752941 0.752941 1" mesh="hip_roll_r_link"/>
        <body name="hip_pitch_r_link" pos="0 -0.122 -0.046">
          <inertial pos="0.001081 8.8e-05 -0.013133" quat="0.706193 -0.0604083 -0.0464278 0.703908" mass="3.95191" diaginertia="0.0155995 0.0108766 0.00930186"/>
          <joint name="hip_pitch_r_joint" pos="0 0 0" axis="0 1 0" range="-2.79253 2.0944" actuatorfrcrange="-330 330"/>
          <geom type="mesh" rgba="0.752941 0.752941 0.752941 1" mesh="hip_pitch_r_link"/>
          <body name="hip_yaw_r_link" pos="0 0 -0.0987">
            <inertial pos="0.004102 0.006542 -0.121068" quat="0.727633 0.0149542 -0.0129439 0.685682" mass="6.6708" diaginertia="0.0533758 0.0495596 0.0178685"/>
            <joint name="hip_yaw_r_joint" pos="0 0 0" axis="0 0 1" range="-1.0472 1.0472" actuatorfrcrange="-235 235"/>
            <geom type="mesh" rgba="0.752941 0.752941 0.752941 1" mesh="hip_yaw_r_link"/>
            <body name="knee_pitch_r_link" pos="0 9.9938e-05 -0.3013">
              <inertial pos="0.00018 -0.001915 -0.178653" quat="0.669257 0.0403837 0.0200239 0.741662" mass="2.31269" diaginertia="0.0309319 0.0304477 0.00269639"/>
              <joint name="knee_pitch_r_joint" pos="0 0 0" axis="0 1 0" range="0 2.3911" actuatorfrcrange="-330 330"/>
              <geom type="mesh" rgba="0.752941 0.752941 0.752941 1" mesh="knee_pitch_r_link"/>
              <body name="ankle_pitch_r_link" pos="0 0.00099989 -0.4">
                <inertial pos="0 0 0" quat="0.5 0.5 -0.5 0.5" mass="0.111609" diaginertia="3.2e-05 1.8e-05 1.8e-05"/>
                <joint name="ankle_pitch_r_joint" pos="0 0 0" axis="0 1 0" range="-1.22173 0.523599" actuatorfrcrange="-55 55"/>
                <geom type="mesh" rgba="0.752941 0.752941 0.752941 1" mesh="ankle_pitch_r_link"/>
                <body name="ankle_roll_r_link">
                  <inertial pos="0.021235 0 -0.032883" quat="0 0.747289 0 0.6645" mass="1.01738" diaginertia="0.0063132 0.006055 0.000954799"/>
                  <joint name="ankle_roll_r_joint" pos="0 0 0" axis="1 0 0" range="-0.523599 0.523599" actuatorfrcrange="-55 55"/>
                  <geom type="mesh" rgba="0.752941 0.752941 0.752941 1" mesh="ankle_roll_r_link"/>
                </body>
              </body>
            </body>
          </body>
        </body>
      </body>
      <body name="body_yaw_link">
        <inertial pos="0.00106104 0.000466623 0.22907" quat="0.99981 0.00186724 -0.015199 -0.012024" mass="22.2" diaginertia="0.445651 0.403894 0.187504"/>
        <joint name="body_yaw_joint" pos="0 0 0" axis="0 0 1" range="-2.96706 3.14159" actuatorfrcrange="-91 91"/>
        <geom type="mesh" rgba="0.752941 0.752941 0.752941 1" mesh="body_yaw_link"/>
        <geom pos="0.090583 0.02375 0.039012" quat="0.337388 -0.621424 0.621426 -0.337389" type="mesh" rgba="0.752941 0.752941 0.752941 1" mesh="camera_body_front_link"/>
        <geom pos="-0.11363 0.02375 0.2746" quat="0.379936 0.596361 -0.596363 -0.379937" type="mesh" rgba="0.752941 0.752941 0.752941 1" mesh="camera_body_back_link"/>
        <body name="head_yaw_link" pos="-0.002 0 0.56508">
          <inertial pos="-0.000202 0.000454 0.007248" quat="0.433079 0.441542 -0.597789 0.510032" mass="0.088397" diaginertia="0.000106995 9.43893e-05 7.56158e-05"/>
          <joint name="head_yaw_joint" pos="0 0 0" axis="0 0 1" range="-1.5708 1.5708" actuatorfrcrange="-6.3 6.3"/>
          <geom type="mesh" rgba="0.752941 0.752941 0.752941 1" mesh="head_yaw_link"/>
          <body name="head_pitch_link" pos="0.01455 0 0.0304" quat="0.991445 0 0.130526 0">
            <inertial pos="-0.000274 0.004118 2.3e-05" quat="0.413438 0.428118 -0.562489 0.573925" mass="0.23046" diaginertia="9.53048e-05 9.17215e-05 5.39737e-05"/>
            <joint name="head_pitch_joint" pos="0 0 0" axis="0 1 0" range="-0.436332 0.436332" actuatorfrcrange="-6.3 6.3"/>
            <geom type="mesh" rgba="0.752941 0.752941 0.752941 1" mesh="head_pitch_link"/>
            <body name="head_roll_link">
              <inertial pos="0.0291315 0.00900748 0.0476541" quat="0.0348881 0.790565 0.385943 0.474171" mass="0.944627" diaginertia="0.0044151 0.00418707 0.00247322"/>
              <joint name="head_roll_joint" pos="0 0 0" axis="1 0 0" range="-0.453786 0.453786" actuatorfrcrange="-6.3 6.3"/>
              <geom type="mesh" rgba="0.752941 0.752941 0.752941 1" mesh="head_roll_link"/>
              <geom pos="0.075191 0.010935 0.074436" quat="0.430457 -0.560985 0.560987 -0.430459" type="mesh" rgba="0.752941 0.752941 0.752941 1" mesh="camera_head_link"/>
            </body>
          </body>
        </body>
        <body name="shoulder_pitch_l_link" pos="0 0.1444 0.37712" quat="0.999048 0.0436192 0 0">
          <inertial pos="0.007494 0.064184 -2e-05" quat="-0.138986 0.691655 0.140135 0.694737" mass="1.0327" diaginertia="0.001247 0.00108933 0.00101366"/>
          <joint name="shoulder_pitch_l_joint" pos="0 0 0" axis="0 1 0" range="-2.96706 2.96706" actuatorfrcrange="-91 91"/>
          <geom type="mesh" rgba="0.752941 0.752941 0.752941 1" mesh="shoulder_pitch_l_link"/>
          <body name="shoulder_roll_l_link" pos="0 0.068 0">
            <inertial pos="0.002389 0.002259 -0.048236" quat="0.699313 0.0770166 0.101863 0.703317" mass="0.440997" diaginertia="0.00131352 0.00100748 0.000904004"/>
            <joint name="shoulder_roll_l_joint" pos="0 0 0" axis="1 0 0" range="-1.0472 1.8326" actuatorfrcrange="-95 95"/>
            <geom type="mesh" rgba="0.752941 0.752941 0.752941 1" mesh="shoulder_roll_l_link"/>
            <body name="shoulder_yaw_l_link" pos="0 0 -0.1025">
              <inertial pos="0.008319 0.002686 -0.112525" quat="0.995878 0.0242664 -0.0546699 -0.0681906" mass="1.36503" diaginertia="0.00974687 0.00961144 0.00120969"/>
              <joint name="shoulder_yaw_l_joint" pos="0 0 0" axis="0 0 1" range="-2.96706 2.96706" actuatorfrcrange="-35 35"/>
              <geom type="mesh" rgba="0.752941 0.752941 0.752941 1" mesh="shoulder_yaw_l_link"/>
              <body name="elbow_pitch_l_link" pos="0.02 0 -0.1975">
                <inertial pos="-0.014694 -7.2e-05 -0.026081" quat="0.379625 0.379479 -0.591752 0.601424" mass="0.246311" diaginertia="0.000406631 0.0003754 0.00022197"/>
                <joint name="elbow_pitch_l_joint" pos="0 0 0" axis="0 1 0" range="-2.61799 0.261799" actuatorfrcrange="-35 35"/>
                <geom type="mesh" rgba="0.752941 0.752941 0.752941 1" mesh="elbow_pitch_l_link"/>
                <body name="elbow_yaw_l_link" pos="-0.02 0 -0.0543">
                  <inertial pos="0.000158 0.001503 -0.069535" quat="0.999822 0.0181014 -0.00149408 -0.00511209" mass="0.986828" diaginertia="0.00310803 0.00303822 0.000576752"/>
                  <joint name="elbow_yaw_l_joint" pos="0 0 0" axis="0 0 1" range="-2.96706 2.96706" actuatorfrcrange="-24 24"/>
                  <geom type="mesh" rgba="0.752941 0.752941 0.752941 1" mesh="elbow_yaw_l_link"/>
                  <body name="wrist_pitch_l_link" pos="0 0 -0.1887">
                    <inertial pos="0.005362 0.00064 -0.018812" quat="0.644732 0.26898 0.632563 0.334417" mass="0.262007" diaginertia="0.000114565 0.000108775 7.06597e-05"/>
                    <joint name="wrist_pitch_l_joint" pos="0 0 0" axis="0 1 0" range="-1.309 1.65806" actuatorfrcrange="-6.3 6.3"/>
                    <geom type="mesh" rgba="0.752941 0.752941 0.752941 1" mesh="wrist_pitch_l_link"/>
                    <body name="wrist_roll_l_link" pos="0 0 -0.02">
                      <inertial pos="0.0284872 0.0452481 0.00236458" quat="0.464011 0.494082 -0.710692 0.188396" mass="0.349937" diaginertia="0.00101907 0.000972428 0.000192285"/>
                      <joint name="wrist_roll_l_joint" pos="0 0 0" axis="1 0 0" range="-1.0472 0.785398" actuatorfrcrange="-6.3 6.3"/>
                      <geom type="mesh" rgba="0.752941 0.752941 0.752941 1" mesh="wrist_roll_l_link"/>
                      <geom pos="0 0 -0.0848" quat="1 0 0 0" type="mesh" rgba="0.752941 0.752941 0.752941 1" mesh="left_tcp_link"/>
                    </body>
                  </body>
                </body>
              </body>
            </body>
          </body>
        </body>
        <body name="shoulder_pitch_r_link" pos="0 -0.1444 0.37712" quat="0.999048 -0.0436192 0 0">
          <inertial pos="0.007494 -0.064184 -2e-05" quat="0.138986 0.691655 -0.140135 0.694737" mass="1.0327" diaginertia="0.001247 0.00108933 0.00101366"/>
          <joint name="shoulder_pitch_r_joint" pos="0 0 0" axis="0 1 0" range="-2.96706 2.96706" actuatorfrcrange="-91 91"/>
          <geom type="mesh" rgba="0.752941 0.752941 0.752941 1" mesh="shoulder_pitch_r_link"/>
          <body name="shoulder_roll_r_link" pos="0 -0.068 0">
            <inertial pos="0.002389 -0.002259 -0.048236" quat="0.703317 0.101863 0.0770166 0.699313" mass="0.440997" diaginertia="0.00131352 0.00100748 0.000904004"/>
            <joint name="shoulder_roll_r_joint" pos="0 0 0" axis="1 0 0" range="-1.8326 1.0472" actuatorfrcrange="-95 95"/>
            <geom type="mesh" rgba="0.752941 0.752941 0.752941 1" mesh="shoulder_roll_r_link"/>
            <body name="shoulder_yaw_r_link" pos="0 0 -0.1025">
              <inertial pos="0.008319 -0.002686 -0.112525" quat="0.995878 -0.0242664 -0.0546699 0.0681906" mass="1.36503" diaginertia="0.00974687 0.00961144 0.00120969"/>
              <joint name="shoulder_yaw_r_joint" pos="0 0 0" axis="0 0 1" range="-2.96706 2.96706" actuatorfrcrange="-35 35"/>
              <geom type="mesh" rgba="0.752941 0.752941 0.752941 1" mesh="shoulder_yaw_r_link"/>
              <body name="elbow_pitch_r_link" pos="0.02 0 -0.1975">
                <inertial pos="-0.014694 7.2e-05 -0.026081" quat="0.379479 0.379625 -0.601424 0.591752" mass="0.246311" diaginertia="0.000406631 0.0003754 0.00022197"/>
                <joint name="elbow_pitch_r_joint" pos="0 0 0" axis="0 1 0" range="-2.61799 0.261799" actuatorfrcrange="-35 35"/>
                <geom type="mesh" rgba="0.752941 0.752941 0.752941 1" mesh="elbow_pitch_r_link"/>
                <body name="elbow_yaw_r_link" pos="-0.02 0 -0.0543">
                  <inertial pos="0.000158 -0.001503 -0.069535" quat="0.999822 -0.0181014 -0.00149408 0.00511209" mass="0.986828" diaginertia="0.00310803 0.00303822 0.000576752"/>
                  <joint name="elbow_yaw_r_joint" pos="0 0 0" axis="0 0 1" range="-2.96706 2.96706" actuatorfrcrange="-24 24"/>
                  <geom type="mesh" rgba="0.752941 0.752941 0.752941 1" mesh="elbow_yaw_r_link"/>
                  <body name="wrist_pitch_r_link" pos="0 0 -0.1887">
                    <inertial pos="0.005362 -0.00064 -0.018812" quat="0.334417 0.632563 0.26898 0.644732" mass="0.262007" diaginertia="0.000114565 0.000108775 7.06597e-05"/>
                    <joint name="wrist_pitch_r_joint" pos="0 0 0" axis="0 1 0" range="-1.309 1.65806" actuatorfrcrange="-6.3 6.3"/>
                    <geom type="mesh" rgba="0.752941 0.752941 0.752941 1" mesh="wrist_pitch_r_link"/>
                    <body name="wrist_roll_r_link" pos="0 0 -0.02">
                      <inertial pos="-0.0273665 0.044373 -0.00316507" quat="0.192356 0.692624 -0.483376 0.499618" mass="0.349937" diaginertia="0.000943092 0.000897478 0.000192716"/>
                      <joint name="wrist_roll_r_joint" pos="0 0 0" axis="1 0 0" range="-0.785398 1.0472" actuatorfrcrange="-6.3 6.3"/>
                      <geom type="mesh" rgba="0.752941 0.752941 0.752941 1" mesh="wrist_roll_r_link"/>
                      <geom pos="0 0 -0.0848" quat="1 0 0 0" type="mesh" rgba="0.752941 0.752941 0.752941 1" mesh="right_tcp_link"/>
                    </body>
                  </body>
                </body>
              </body>
            </body>
          </body>
        </body>
      </body>
    </body>
  </worldbody>
</mujoco>
